<?xml version="1.0"?>
<robot xmlns:xacro="http://www.ros.org/wiki/xacro" >


    <material name="white">
        <color rgba="1 1 1 1" />
    </material>

    <material name="orange">
        <color rgba="1 0.3 0.1 1"/>
    </material>

    <material name="blue">
        <color rgba="0.2 0.2 1 1"/>
    </material>

    <material name="black">
        <color rgba="0 0 0 1"/>
    </material>

    <material name="red">
        <color rgba="1 0 0 1"/>
    </material>
    
    <!-- BASE LINK -->

    <link name="base_link">

    </link>


    <!-- CHASSIS LINK -->

    <joint name="chassis_joint" type="fixed">
        <parent link="base_link"/>
        <child link="chassis"/>
        <origin xyz="-0.05 0 0"/>
    </joint>

    <link name="chassis">
        <visual>
            <origin xyz="0.2 0 0.027"/>
            <geometry>
                <box size="0.4 0.4 0.08"/>
            </geometry>
            <material name="white"/>
        </visual>
        <collision>
            <origin xyz="0.2 0 0.027"/>
            <geometry>
                <box size="0.4 0.4 0.08"/>
            </geometry>
        </collision>
    </link>
    
    <!-- LEFT WHEEL LINK -->

    <joint name="left_wheel_joint" type="continuous">
        <parent link="base_link"/>
        <child link="left_wheel"/>
        <origin xyz="0 0.16075 0" rpy="-${pi/2} 0 0" />
        <axis xyz="0 0 1"/>
    </joint>

    <link name="left_wheel">
        <visual>
            <geometry>
                <cylinder radius="0.033" length="0.0265"/>
            </geometry>
            <material name="blue"/>
        </visual>
        <collision>
            <geometry>
                <cylinder radius="0.033" length="0.0265"/>
            </geometry>
        </collision>
    </link>

    <!-- RIGHT WHEEL LINK -->

    <joint name="right_wheel_joint" type="continuous">
        <parent link="base_link"/>
        <child link="right_wheel"/>
        <origin xyz="0 -0.16075 0" rpy="${pi/2} 0 0" />
        <axis xyz="0 0 -1"/>
    </joint>

    <link name="right_wheel">
        <visual>
            <geometry>
                <cylinder radius="0.033" length="0.0265"/>
            </geometry>
            <material name="blue"/>
        </visual>
        <collision>
            <geometry>
                <cylinder radius="0.033" length="0.0265"/>
            </geometry>
        </collision>
    </link>

    <!-- CASTER WHEEL LINK -->

    <joint name="left_caster_wheel_joint" type="fixed">
        <parent link="chassis"/>
        <child link="left_caster_wheel"/>
        <origin xyz="0.314 0.150 -0.0205"/>
    </joint>


    <link name="left_caster_wheel">
        <visual>
            <geometry>
                <sphere radius="0.0125"/>
            </geometry>
            <material name="black"/>
        </visual>
        <collision>
            <geometry>
                <sphere radius="0.0125"/>
            </geometry>
        </collision>
        
    </link>

    <joint name="right_caster_wheel_joint" type="fixed">
        <parent link="chassis"/>
        <child link="right_caster_wheel"/>
        <origin xyz="0.314 -0.150 -0.0205"/>
    </joint>


    <link name="right_caster_wheel">
        <visual>
            <geometry>
                <sphere radius="0.0125"/>
            </geometry>
            <material name="black"/>
        </visual>
        <collision>
            <geometry>
                <sphere radius="0.0125"/>
            </geometry>
        </collision>
        
    </link>

    
    
</robot>